<?xml version="1.0" ?>
<!--
SO101 robot model with wrist camera.
Based on so101_new_calib.xml from SO-ARM100 submodule, with wrist camera added.
Mesh files are referenced from the submodule.
-->
<mujoco model="so101_with_wrist_cam">
  <!-- Point to mesh files in submodule -->
  <compiler angle="radian" meshdir="../assets/SO-ARM100/Simulation/SO101/assets" autolimits="true"/>

  <!-- Global simulation options for reliable collision -->
  <option timestep="0.002" impratio="1" gravity="0 0 -9.81" cone="elliptic" noslip_iterations="10"/>

  <visual>
    <headlight diffuse="0.6 0.6 0.6" ambient="0.3 0.3 0.3" specular="0 0 0" />
    <rgba haze="0.15 0.25 0.35 1" />
    <global azimuth="160" elevation="-20" offwidth="1920" offheight="1080"/>
    <quality shadowsize="4096"/>
  </visual>

  <default>
    <default class="so101_new_calib">
      <joint damping="1" frictionloss="0.1" armature="0.005"/>
      <position kp="50"/>
      <default class="visual">
        <geom type="mesh" contype="0" conaffinity="0" group="2"/>
      </default>
      <default class="collision">
        <geom group="3" contype="3" conaffinity="3"/>
      </default>
    </default>
    <default class="sts3215">
      <geom contype="0" conaffinity="0"/>
      <joint damping="0.60" frictionloss="0.052" armature="0.028"/>
      <position kp="17.8"/>
    </default>
    <default class="backlash">
      <joint damping="0.01" frictionloss="0" armature="0.01" limited="true" range="-0.008726646259971648 0.008726646259971648"/>
    </default>
  <default class="fingerpad">
    <geom
      type="box"
      size="0.004 0.015 0.010"
      friction="100 10 0.1"
      condim="6"
      solref="0.002 1"
      solimp="0.999 0.9999 0.00001"
      contype="3"
      conaffinity="3"
      rgba="0.15 0.15 0.15 0.2"
      group="0"
      priority="1"/>
  </default>
  </default>

  <asset>
    <!-- Textures and materials for scene -->
    <texture type="skybox" builtin="gradient" rgb1="0.3 0.5 0.7" rgb2="0 0 0" width="512" height="3072" />
    <texture type="2d" name="groundplane" builtin="checker" mark="edge" rgb1="0.2 0.3 0.4" rgb2="0.1 0.2 0.3" markrgb="0.8 0.8 0.8" width="300" height="300" />
    <material name="groundplane" texture="groundplane" texuniform="true" texrepeat="5 5" reflectance="0.2" />
    <material name="duplo_white" rgba="0.95 0.95 0.95 1" />

    <!-- Robot meshes from submodule -->
    <mesh file="waveshare_mounting_plate_so101_v2.stl"/>
    <mesh file="sts3215_03a_v1.stl"/>
    <mesh file="motor_holder_so101_base_v1.stl"/>
    <mesh file="wrist_roll_follower_so101_v1.stl"/>
    <mesh file="moving_jaw_so101_v1.stl"/>
    <mesh file="base_motor_holder_so101_v1.stl"/>
    <mesh file="upper_arm_so101_v1.stl"/>
    <mesh file="wrist_roll_pitch_so101_v2.stl"/>
    <mesh file="under_arm_so101_v1.stl"/>
    <mesh file="rotation_pitch_so101_v1.stl"/>
    <mesh file="motor_holder_so101_wrist_v1.stl"/>
    <mesh file="sts3215_03a_no_horn_v1.stl"/>
    <mesh file="base_so101_v2.stl"/>

    <!-- Robot materials -->
    <material name="base_motor_holder_so101_v1_material" rgba="1 0.82 0.12 1"/>
    <material name="base_so101_v2_material" rgba="1 0.82 0.12 1"/>
    <material name="sts3215_03a_v1_material" rgba="0.1 0.1 0.1 1"/>
    <material name="waveshare_mounting_plate_so101_v2_material" rgba="1 0.82 0.12 1"/>
    <material name="motor_holder_so101_base_v1_material" rgba="1 0.82 0.12 1"/>
    <material name="rotation_pitch_so101_v1_material" rgba="1 0.82 0.12 1"/>
    <material name="upper_arm_so101_v1_material" rgba="1 0.82 0.12 1"/>
    <material name="under_arm_so101_v1_material" rgba="1 0.82 0.12 1"/>
    <material name="motor_holder_so101_wrist_v1_material" rgba="1 0.82 0.12 1"/>
    <material name="sts3215_03a_no_horn_v1_material" rgba="0.1 0.1 0.1 1.0"/>
    <material name="wrist_roll_pitch_so101_v2_material" rgba="1 0.82 0.12 1"/>
    <material name="wrist_roll_follower_so101_v1_material" rgba="1 0.82 0.12 1"/>
    <material name="moving_jaw_so101_v1_material" rgba="1 0.82 0.12 1"/>
  </asset>

  <worldbody>
    <!-- Scene elements -->
    <light pos="0 0 3.5" dir="0 0 -1" directional="true" />
    <geom name="floor" size="0 0 0.05" pos="0 0 0" type="plane" material="groundplane" contype="1" conaffinity="3"/>

    <!-- Overhead camera (Nuroum V11: 90° diagonal FOV -> ~52° vertical for 16:9) -->
    <camera name="overhead_cam" pos="0.3 -0.09 0.6" axisangle="0 0 1 -1.5708" fovy="52"/>

    <!-- Bowl/container for pick and place target -->
    <!-- Position: moved 10cm right (-Y) -->
    <!-- Square container with thin walls, 12cm x 12cm x 3cm deep -->
    <body name="bowl" pos="0.217 -0.225 0.0">
      <!-- Base (thin plate) -->
      <geom name="bowl_base" type="box" size="0.06 0.06 0.002" pos="0 0 0.002" rgba="0.85 0.85 0.8 1"
        contype="1" conaffinity="3" friction="0.5 0.5 0.01"/>
      <!-- Walls (4 sides) -->
      <geom name="bowl_wall_px" type="box" size="0.003 0.06 0.015" pos="0.06 0 0.017" rgba="0.85 0.85 0.8 1"
        contype="1" conaffinity="3" friction="0.3 0.3 0.01"/>
      <geom name="bowl_wall_nx" type="box" size="0.003 0.06 0.015" pos="-0.06 0 0.017" rgba="0.85 0.85 0.8 1"
        contype="1" conaffinity="3" friction="0.3 0.3 0.01"/>
      <geom name="bowl_wall_py" type="box" size="0.06 0.003 0.015" pos="0 0.06 0.017" rgba="0.85 0.85 0.8 1"
        contype="1" conaffinity="3" friction="0.3 0.3 0.01"/>
      <geom name="bowl_wall_ny" type="box" size="0.06 0.003 0.015" pos="0 -0.06 0.017" rgba="0.85 0.85 0.8 1"
        contype="1" conaffinity="3" friction="0.3 0.3 0.01" mass="0.1"/>
    </body>

    <!-- White Duplo 2x4 brick for pick and place task -->
    <!-- Duplo 2x4: 64mm x 32mm x 19.2mm body + 4.5mm studs -->
    <!-- Position: moved 10cm left (+Y) -->
    <body name="duplo" pos="0.217 0.225 0.0096">
      <freejoint name="duplo_joint"/>
      <!-- Main brick body - high friction for gripping -->
      <geom name="duplo_body" type="box" size="0.032 0.016 0.0096" material="duplo_white" mass="0.03"
        contype="3" conaffinity="3" friction="100 10 0.1" condim="6" margin="0.001"
        solref="0.002 1" solimp="0.999 0.9999 0.00001"/>
      <!-- Studs (8 total: 4x2 grid, 16mm spacing, 9.6mm diameter, 4.5mm tall) -->
      <!-- Row 1 (y = -0.008) -->
      <geom name="stud_1" type="cylinder" size="0.0048 0.00225" pos="-0.024 -0.008 0.012" material="duplo_white" contype="3" conaffinity="3" friction="100 10 0.1"/>
      <geom name="stud_2" type="cylinder" size="0.0048 0.00225" pos="-0.008 -0.008 0.012" material="duplo_white" contype="3" conaffinity="3" friction="100 10 0.1"/>
      <geom name="stud_3" type="cylinder" size="0.0048 0.00225" pos="0.008 -0.008 0.012" material="duplo_white" contype="3" conaffinity="3" friction="100 10 0.1"/>
      <geom name="stud_4" type="cylinder" size="0.0048 0.00225" pos="0.024 -0.008 0.012" material="duplo_white" contype="3" conaffinity="3" friction="100 10 0.1"/>
      <!-- Row 2 (y = +0.008) -->
      <geom name="stud_5" type="cylinder" size="0.0048 0.00225" pos="-0.024 0.008 0.012" material="duplo_white" contype="3" conaffinity="3" friction="100 10 0.1"/>
      <geom name="stud_6" type="cylinder" size="0.0048 0.00225" pos="-0.008 0.008 0.012" material="duplo_white" contype="3" conaffinity="3" friction="100 10 0.1"/>
      <geom name="stud_7" type="cylinder" size="0.0048 0.00225" pos="0.008 0.008 0.012" material="duplo_white" contype="3" conaffinity="3" friction="100 10 0.1"/>
      <geom name="stud_8" type="cylinder" size="0.0048 0.00225" pos="0.024 0.008 0.012" material="duplo_white" contype="3" conaffinity="3" friction="100 10 0.1"/>
    </body>

    <!-- Robot arm -->
    <body name="base" pos="0 0 0" quat="1 0 0 0" childclass="so101_new_calib">
      <inertial pos="0.0137179 -5.19711e-05 0.0334843" mass="0.147" fullinertia="0.000114686 0.000136117 0.000130364 -4.59787e-07 4.97151e-06 9.75275e-08"/>
      <geom type="mesh" class="visual" pos="-0.00636471 -9.94414e-05 -0.0024" quat="0.5 0.5 0.5 0.5" mesh="base_motor_holder_so101_v1" material="base_motor_holder_so101_v1_material"/>
      <geom type="mesh" class="visual" pos="-0.00636471 -8.97657e-09 -0.0024" quat="0.5 0.5 0.5 0.5" mesh="base_so101_v2" material="base_so101_v2_material"/>
      <geom type="mesh" class="visual" pos="0.0263353 -8.97657e-09 0.0437" quat="1 -2.85511e-16 -9.64433e-17 6.12908e-16" mesh="sts3215_03a_v1" material="sts3215_03a_v1_material"/>
      <geom type="mesh" class="visual" pos="-0.0309827 -0.000199441 0.0474" quat="0.5 0.5 0.5 0.5" mesh="waveshare_mounting_plate_so101_v2" material="waveshare_mounting_plate_so101_v2_material"/>
      <site group="3" name="baseframe" pos="8.67362e-19 9.55596e-18 3.46945e-18" quat="1 -8.17396e-19 3.78392e-17 2.22045e-16"/>

      <body name="shoulder" pos="0.0388353 -8.97657e-09 0.0624" quat="3.56167e-16 1.22818e-15 -1 -4.14635e-16">
        <joint axis="0 0 1" name="shoulder_pan" type="hinge" range="-1.9198621771937616 1.9198621771937634" class="sts3215"/>
        <inertial pos="-0.0307604 -1.66727e-05 -0.0252713" mass="0.100006" fullinertia="8.3759e-05 8.10403e-05 2.39783e-05 7.55525e-08 -1.16342e-06 1.54663e-07"/>
        <geom type="mesh" class="visual" pos="-0.0303992 0.000422241 -0.0417" quat="0.5 0.5 0.5 -0.5" mesh="sts3215_03a_v1" material="sts3215_03a_v1_material"/>
        <geom type="mesh" class="collision" pos="-0.0303992 0.000422241 -0.0417" quat="0.5 0.5 0.5 -0.5" mesh="sts3215_03a_v1" material="sts3215_03a_v1_material"/>
        <geom type="mesh" class="visual" pos="-0.0675992 -0.000177759 0.0158499" quat="0.5 0.5 -0.5 0.5" mesh="motor_holder_so101_base_v1" material="motor_holder_so101_base_v1_material"/>
        <geom type="mesh" class="collision" pos="-0.0675992 -0.000177759 0.0158499" quat="0.5 0.5 -0.5 0.5" mesh="motor_holder_so101_base_v1" material="motor_holder_so101_base_v1_material"/>
        <geom type="mesh" class="visual" pos="0.0122008 2.22413e-05 0.0464" quat="0.707107 -0.707107 -0 8.3163e-34" mesh="rotation_pitch_so101_v1" material="rotation_pitch_so101_v1_material"/>
        <geom type="mesh" class="collision" pos="0.0122008 2.22413e-05 0.0464" quat="0.707107 -0.707107 -0 8.3163e-34" mesh="rotation_pitch_so101_v1" material="rotation_pitch_so101_v1_material"/>

        <body name="upper_arm" pos="-0.0303992 -0.0182778 -0.0542" quat="0.5 -0.5 -0.5 -0.5">
          <joint axis="0 0 1" name="shoulder_lift" type="hinge" range="-1.7453292519943224 1.7453292519943366" class="sts3215"/>
          <inertial pos="-0.0898471 -0.00838224 0.0184089" mass="0.103" fullinertia="4.08002e-05 0.000147318 0.000142487 -1.97819e-05 -4.03016e-08 8.97326e-09"/>
          <geom type="mesh" class="visual" pos="-0.11257 -0.0155 0.0187" quat="4.56308e-16 -0.707107 0.707107 -1.37383e-16" mesh="sts3215_03a_v1" material="sts3215_03a_v1_material"/>
          <geom type="mesh" class="collision" pos="-0.11257 -0.0155 0.0187" quat="4.56308e-16 -0.707107 0.707107 -1.37383e-16" mesh="sts3215_03a_v1" material="sts3215_03a_v1_material"/>
          <geom type="mesh" class="visual" pos="-0.065085 0.012 0.0182" quat="0 1 0 0" mesh="upper_arm_so101_v1" material="upper_arm_so101_v1_material"/>
          <geom type="mesh" class="collision" pos="-0.065085 0.012 0.0182" quat="0 1 0 0" mesh="upper_arm_so101_v1" material="upper_arm_so101_v1_material"/>

          <body name="lower_arm" pos="-0.11257 -0.028 1.73763e-16" quat="0.707107 -5.98613e-17 -2.58051e-17 0.707107">
            <joint axis="0 0 1" name="elbow_flex" type="hinge" range="-1.69 1.69" class="sts3215"/>
            <inertial pos="-0.0980701 0.00324376 0.0182831" mass="0.104" fullinertia="2.87438e-05 0.000159844 0.00014529 7.41152e-06 1.26409e-06 -4.90188e-08"/>
            <geom type="mesh" class="visual" pos="-0.0648499 -0.032 0.0182" quat="0 1 0 0" mesh="under_arm_so101_v1" material="under_arm_so101_v1_material"/>
            <geom type="mesh" class="collision" pos="-0.0648499 -0.032 0.0182" quat="0 1 0 0" mesh="under_arm_so101_v1" material="under_arm_so101_v1_material"/>
            <geom type="mesh" class="visual" pos="-0.0648499 -0.032 0.018" quat="3.92687e-16 -1 -1.9186e-15 -6.38378e-16" mesh="motor_holder_so101_wrist_v1" material="motor_holder_so101_wrist_v1_material"/>
            <geom type="mesh" class="collision" pos="-0.0648499 -0.032 0.018" quat="3.92687e-16 -1 -1.9186e-15 -6.38378e-16" mesh="motor_holder_so101_wrist_v1" material="motor_holder_so101_wrist_v1_material"/>
            <geom type="mesh" class="visual" pos="-0.1224 0.0052 0.0187" quat="7.21645e-16 1.56949e-15 1 -3.33067e-16" mesh="sts3215_03a_v1" material="sts3215_03a_v1_material"/>
            <geom type="mesh" class="collision" pos="-0.1224 0.0052 0.0187" quat="7.21645e-16 1.56949e-15 1 -3.33067e-16" mesh="sts3215_03a_v1" material="sts3215_03a_v1_material"/>

            <body name="wrist" pos="-0.1349 0.0052 3.62355e-17" quat="0.707107 9.58722e-16 -7.51313e-16 -0.707107">
              <joint axis="0 0 1" name="wrist_flex" type="hinge" range="-1.6580628494556928 1.6580627293335335" class="sts3215"/>
              <inertial pos="-0.000103312 -0.0386143 0.0281156" mass="0.079" fullinertia="3.68263e-05 2.5391e-05 2.1e-05 1.7893e-08 -5.28128e-08 3.6412e-06"/>
              <geom type="mesh" class="visual" pos="8.32667e-17 -0.0424 0.0306" quat="0.5 0.5 0.5 -0.5" mesh="sts3215_03a_no_horn_v1" material="sts3215_03a_no_horn_v1_material"/>
              <geom type="mesh" class="collision" pos="8.32667e-17 -0.0424 0.0306" quat="0.5 0.5 0.5 -0.5" mesh="sts3215_03a_no_horn_v1" material="sts3215_03a_no_horn_v1_material"/>
              <geom type="mesh" class="visual" pos="0 -0.028 0.0181" quat="0.5 -0.5 -0.5 -0.5" mesh="wrist_roll_pitch_so101_v2" material="wrist_roll_pitch_so101_v2_material"/>
              <geom type="mesh" class="collision" pos="0 -0.028 0.0181" quat="0.5 -0.5 -0.5 -0.5" mesh="wrist_roll_pitch_so101_v2" material="wrist_roll_pitch_so101_v2_material"/>

              <body name="gripper" pos="5.55112e-17 -0.0611 0.0181" quat="0.0172091 -0.0172091 0.706897 0.706897">
                <joint axis="0 0 1" name="wrist_roll" type="hinge" range="-2.7438472969992493 2.841206309382605" class="sts3215"/>
                <inertial pos="0.000213627 0.000245138 -0.025187" mass="0.087" fullinertia="2.75087e-05 4.33657e-05 3.45059e-05 -3.35241e-07 -5.7352e-06 -5.17847e-08"/>
                <geom type="mesh" class="visual" pos="0.0077 0.0001 -0.0234" quat="0.707107 -0.707107 1.66015e-15 6.45094e-15" mesh="sts3215_03a_v1" material="sts3215_03a_v1_material"/>
                <geom type="mesh" class="collision" pos="0.0077 0.0001 -0.0234" quat="0.707107 -0.707107 1.66015e-15 6.45094e-15" mesh="sts3215_03a_v1" material="sts3215_03a_v1_material"/>
                <geom type="mesh" class="visual" pos="8.32667e-17 -0.000218214 0.000949706" quat="0 1 0 0" mesh="wrist_roll_follower_so101_v1" material="wrist_roll_follower_so101_v1_material"/>
                <!-- Mesh collision disabled - using box primitives instead -->
                <geom type="mesh" class="visual" pos="8.32667e-17 -0.000218214 0.000949706" quat="0 1 0 0" mesh="wrist_roll_follower_so101_v1" contype="0" conaffinity="0" group="3"/>
                <site group="3" name="gripperframe" pos="-0.0079 -0.000218121 -0.0981274" quat="0.707107 -0 0.707107 -2.37788e-17"/>

                <!-- Fixed jaw finger pad (gripping surface) - BRIGHT RED for debugging -->
                <geom name="fixed_pad"
                  type="box"                  
                  size="0.001 0.0065 0.015"
                  pos="-0.0085 0.0 -0.0894"
                  contype="3"
                  conaffinity="3"
                  friction="100 10 0.1"
                  condim="6"
                  margin="0.002"
                  solref="0.002 1"
                  solimp="0.999 0.9999 0.00001"
                  rgba="0 0 0 1"
                  priority="1"
                  group="0"/>

                <!--
                ================= WRIST CAMERA =================
                Edit pos and quat to adjust camera position/orientation.
                Use adjust_wrist_camera.py to find the right values interactively.
                Camera looks along its -Z axis by default.
                -->
                
                <!-- 1) Anchor -->
                <body name="cam_anchor"
                      pos="0 0 -0.045"
                      quat="1 0 0 0">

                  <!-- 2) Left/right correction (your Z 180° flip) -->
                  <body name="cam_yawfix"
                        axisangle="0 0 1 3.14159265">

                    <!-- 3) Physical camera offset -->
                    <body name="cam_slide"
                          pos="0.000 0.039 -0.01">

                      <!-- 4) Pitch down to see the jaws -->
                      <body name="cam_pitch"
                            axisangle="1 0 0 -0.7">

                        <camera name="wrist_cam"
                                pos="0 0 0"
                                fovy="71"/>

                        <!-- Visual representation of camera (camera looks along -Z) -->
                        <geom name="cam_body" type="box" size="0.008 0.012 0.006" pos="0 0 0.008"
                              rgba="0.2 0.2 0.2 1" contype="0" conaffinity="0"/>
                        <geom name="cam_lens" type="cylinder" size="0.005 0.004" pos="0 0 0"
                              rgba="0.1 0.1 0.3 1" contype="0" conaffinity="0"/>

                      </body>
                    </body>
                  </body>
                </body>

                <body name="moving_jaw_so101_v1" pos="0.0202 0.0188 -0.0234" quat="0.707107 0.707107 -1.85362e-08 1.85362e-08">
                  <joint axis="0 0 1" name="gripper" type="hinge" range="-0.17453297762778586 1.7453291995659765" class="sts3215"/>
                  <inertial pos="-0.00157495 -0.0300244 0.0192755" mass="0.012" fullinertia="6.61427e-06 1.89032e-06 5.28738e-06 -3.19807e-07 -5.90717e-09 -1.09945e-07"/>
                  <geom type="mesh" class="visual" pos="-5.55112e-17 -5.55112e-17 0.0189" quat="1 -0 3.00524e-16 -2.00834e-17" mesh="moving_jaw_so101_v1" material="moving_jaw_so101_v1_material"/>
                  <!-- Mesh collision disabled - using finger pad only -->
                  <geom type="mesh" class="visual" pos="-5.55112e-17 -5.55112e-17 0.0189" quat="1 -0 3.00524e-16 -2.00834e-17" mesh="moving_jaw_so101_v1" contype="0" conaffinity="0" group="3"/>

                  <!-- Moving jaw finger pad (gripping surface) - BRIGHT GREEN for debugging -->
                  <geom name="moving_pad"
                    type="box"
                    size="0.001 0.0065 0.015"
                    pos="-0.012 -0.0669 0.018"
                    axisangle="1 0 0 1.5708"
                    contype="3"
                    conaffinity="3"
                    friction="100 10 0.1"
                    condim="6"
                    margin="0.002"
                    solref="0.002 1"
                    solimp="0.999 0.9999 0.00001"
                    rgba="0 0 0 1"
                    priority="1"
                    group="0"/>

                </body>
              </body>
            </body>
          </body>
        </body>
      </body>
    </body>
  </worldbody>

  <!-- Contact pairs to override friction for specific geom combinations -->
  <contact>
    <!-- Low friction between Duplo and floor (so it falls/slides naturally) -->
    <pair geom1="floor" geom2="duplo_body" friction="0.5 0.5 0.005 0.0001 0.0001"/>
    <pair geom1="floor" geom2="stud_1" friction="0.5 0.5 0.005 0.0001 0.0001"/>
    <pair geom1="floor" geom2="stud_2" friction="0.5 0.5 0.005 0.0001 0.0001"/>
    <pair geom1="floor" geom2="stud_3" friction="0.5 0.5 0.005 0.0001 0.0001"/>
    <pair geom1="floor" geom2="stud_4" friction="0.5 0.5 0.005 0.0001 0.0001"/>
    <pair geom1="floor" geom2="stud_5" friction="0.5 0.5 0.005 0.0001 0.0001"/>
    <pair geom1="floor" geom2="stud_6" friction="0.5 0.5 0.005 0.0001 0.0001"/>
    <pair geom1="floor" geom2="stud_7" friction="0.5 0.5 0.005 0.0001 0.0001"/>
    <pair geom1="floor" geom2="stud_8" friction="0.5 0.5 0.005 0.0001 0.0001"/>
    <!-- Low friction between finger pads and floor (so gripper doesn't stick) -->
    <pair geom1="floor" geom2="fixed_pad" friction="0.3 0.3 0.001 0.0001 0.0001"/>
    <pair geom1="floor" geom2="moving_pad" friction="0.3 0.3 0.001 0.0001 0.0001"/>
    <!-- Low friction between Duplo and bowl (so it slides in naturally) -->
    <pair geom1="bowl_base" geom2="duplo_body" friction="0.3 0.3 0.005 0.0001 0.0001"/>
    <pair geom1="bowl_wall_px" geom2="duplo_body" friction="0.3 0.3 0.005 0.0001 0.0001"/>
    <pair geom1="bowl_wall_nx" geom2="duplo_body" friction="0.3 0.3 0.005 0.0001 0.0001"/>
    <pair geom1="bowl_wall_py" geom2="duplo_body" friction="0.3 0.3 0.005 0.0001 0.0001"/>
    <pair geom1="bowl_wall_ny" geom2="duplo_body" friction="0.3 0.3 0.005 0.0001 0.0001"/>
  </contact>

  <actuator>
    <position class="sts3215" name="shoulder_pan" joint="shoulder_pan" forcerange="-3.35 3.35" ctrlrange="-1.91986 1.91986"/>
    <position class="sts3215" name="shoulder_lift" joint="shoulder_lift" forcerange="-3.35 3.35" ctrlrange="-1.74533 1.74533"/>
    <position class="sts3215" name="elbow_flex" joint="elbow_flex" forcerange="-3.35 3.35" ctrlrange="-1.69 1.69"/>
    <position class="sts3215" name="wrist_flex" joint="wrist_flex" forcerange="-3.35 3.35" ctrlrange="-1.65806 1.65806"/>
    <position class="sts3215" name="wrist_roll" joint="wrist_roll" forcerange="-3.35 3.35" ctrlrange="-2.74385 2.84121"/>
    <position class="sts3215" name="gripper" joint="gripper" forcerange="-3.35 3.35" ctrlrange="-0.17453 1.74533"/>
  </actuator>
</mujoco>
